<?xml version="1.0" ?>
<robot name="robot">
  <material name="silver">
    <color rgba="0.700 0.700 0.700 1.000"/>
  </material>
   <material name="blue">
      <color rgba="0 0 1 1"/>
   </material>
  <transmission name="Revolute 1_tran">
    <type>transmission_interface/SimpleTransmission</type>
    <joint name="Revolute 1">
      <hardwareInterface>hardware_interface/EffortJointInterface</hardwareInterface>
    </joint>
    <actuator name="Revolute 1_actr">
      <hardwareInterface>hardware_interface/EffortJointInterface</hardwareInterface>
      <mechanicalReduction>1</mechanicalReduction>
    </actuator>
  </transmission>
  <transmission name="Revolute 2_tran">
    <type>transmission_interface/SimpleTransmission</type>
    <joint name="Revolute 2">
      <hardwareInterface>hardware_interface/EffortJointInterface</hardwareInterface>
    </joint>
    <actuator name="Revolute 2_actr">
      <hardwareInterface>hardware_interface/EffortJointInterface</hardwareInterface>
      <mechanicalReduction>1</mechanicalReduction>
    </actuator>
  </transmission>
  <transmission name="Revolute 3_tran">
    <type>transmission_interface/SimpleTransmission</type>
    <joint name="Revolute 3">
      <hardwareInterface>hardware_interface/EffortJointInterface</hardwareInterface>
    </joint>
    <actuator name="Revolute 3_actr">
      <hardwareInterface>hardware_interface/EffortJointInterface</hardwareInterface>
      <mechanicalReduction>1</mechanicalReduction>
    </actuator>
  </transmission>
  <transmission name="Revolute 4_tran">
    <type>transmission_interface/SimpleTransmission</type>
    <joint name="Revolute 4">
      <hardwareInterface>hardware_interface/EffortJointInterface</hardwareInterface>
    </joint>
    <actuator name="Revolute 4_actr">
      <hardwareInterface>hardware_interface/EffortJointInterface</hardwareInterface>
      <mechanicalReduction>1</mechanicalReduction>
    </actuator>
  </transmission>
  <gazebo>
    <plugin filename="libgazebo_ros_control.so" name="control"/>
  </gazebo>
  <gazebo reference="base_link">
    <material>Gazebo/Silver</material>
    <mu1>0.2</mu1>
    <mu2>0.2</mu2>
    <selfCollide>true</selfCollide>
    <gravity>true</gravity>
  </gazebo>
  <gazebo reference="caster_wheel_1">
    <material>Gazebo/Silver</material>
    <mu1>0.2</mu1>
    <mu2>0.2</mu2>
    <selfCollide>true</selfCollide>
  </gazebo>
  <gazebo reference="caster_fork_1">
    <material>Gazebo/Silver</material>
    <mu1>0.2</mu1>
    <mu2>0.2</mu2>
    <selfCollide>true</selfCollide>
  </gazebo>
  <gazebo reference="left_wheel_1">
    <material>Gazebo/Silver</material>
    <mu1>0.2</mu1>
    <mu2>0.2</mu2>
    <selfCollide>true</selfCollide>
  </gazebo>
  <gazebo reference="right_wheel_1">
    <material>Gazebo/Silver</material>
    <mu1>0.2</mu1>
    <mu2>0.2</mu2>
    <selfCollide>true</selfCollide>
  </gazebo>
  <link name="base_link">
    <inertial>
      <origin rpy="0 0 0" xyz="-1.514808277263353e-17 5.101665553979481e-05 0.019999664794410715"/>
      <mass value="1.2728533351045312"/>
      <inertia ixx="0.004415" ixy="0.0" ixz="0.0" iyy="0.00256" iyz="-0.0" izz="0.006635"/>
    </inertial>
    <visual>
      <origin rpy="0 0 0" xyz="0 0 0"/>
      <geometry>
        <mesh filename="meshes/base_link.stl" scale="0.001 0.001 0.001"/>
      </geometry>
      <material name="silver"/>
    </visual>
    <collision>
      <origin rpy="0 0 0" xyz="0 0 0"/>
      <geometry>
        <mesh filename="meshes/base_link.stl" scale="0.001 0.001 0.001"/>
      </geometry>
    </collision>
  </link>
  <link name="caster_wheel_1">
    <inertial>
      <origin rpy="0 0 0" xyz="-0.005000000000000495 -2.058718588243691e-07 -2.149933009398808e-12"/>
      <mass value="0.0016434456569091604"/>
      <inertia ixx="0.0" ixy="0.0" ixz="0.0" iyy="0.0" iyz="0.0" izz="0.0"/>
    </inertial>
    <visual>
      <origin rpy="0 0 0" xyz="-0.005 0.071557 0.0125"/>
      <geometry>
        <mesh filename="meshes/caster_wheel_1.stl" scale="0.001 0.001 0.001"/>
      </geometry>
      <material name="silver"/>
    </visual>
    <collision>
      <origin rpy="0 0 0" xyz="-0.005 0.071557 0.0125"/>
      <geometry>
        <mesh filename="meshes/caster_wheel_1.stl" scale="0.001 0.001 0.001"/>
      </geometry>
    </collision>
  </link>
  <link name="caster_fork_1">
    <inertial>
      <origin rpy="0 0 0" xyz="-4.828898138961918e-16 0.003917233985619384 -0.006001009388864729"/>
      <mass value="0.001842425119376973"/>
      <inertia ixx="0.0" ixy="-0.0" ixz="-0.0" iyy="0.0" iyz="0.0" izz="0.0"/>
    </inertial>
    <visual>
      <origin rpy="0 0 0" xyz="-0.0 0.08 0.001"/>
      <geometry>
        <mesh filename="meshes/caster_fork_1.stl" scale="0.001 0.001 0.001"/>
      </geometry>
      <material name="silver"/>
    </visual>
    <collision>
      <origin rpy="0 0 0" xyz="-0.0 0.08 0.001"/>
      <geometry>
        <mesh filename="meshes/caster_fork_1.stl" scale="0.001 0.001 0.001"/>
      </geometry>
    </collision>
  </link>
  <link name="left_wheel_1">
    <inertial>
      <origin rpy="0 0 0" xyz="0.009999999999999995 0.0 0.0"/>
      <mass value="0.09349379737083224"/>
      <inertia ixx="7.5e-05" ixy="0.0" ixz="0.0" iyy="4.1e-05" iyz="0.0" izz="4.1e-05"/>
    </inertial>
    <visual>
      <origin rpy="0 0 0" xyz="-0.08 -0.08 -0.02"/>
      <geometry>
        <mesh filename="meshes/left_wheel_1.stl" scale="0.001 0.001 0.001"/>
      </geometry>
      <material name="silver"/>
    </visual>
    <collision>
      <origin rpy="0 0 0" xyz="-0.08 -0.08 -0.02"/>
      <geometry>
        <mesh filename="meshes/left_wheel_1.stl" scale="0.001 0.001 0.001"/>
      </geometry>
    </collision>
  </link>
  <link name="right_wheel_1">
    <inertial>
      <origin rpy="0 0 0" xyz="-0.009999999999999995 0.0 0.0"/>
      <mass value="0.09349379737083224"/>
      <inertia ixx="7.5e-05" ixy="-0.0" ixz="0.0" iyy="4.1e-05" iyz="0.0" izz="4.1e-05"/>
    </inertial>
    <visual>
      <origin rpy="0 0 0" xyz="0.08 -0.08 -0.02"/>
      <geometry>
        <mesh filename="meshes/right_wheel_1.stl" scale="0.001 0.001 0.001"/>
      </geometry>
      <material name="silver"/>
    </visual>
    <collision>
      <origin rpy="0 0 0" xyz="0.08 -0.08 -0.02"/>
      <geometry>
        <mesh filename="meshes/right_wheel_1.stl" scale="0.001 0.001 0.001"/>
      </geometry>
    </collision>
  </link>
  <link name="camera_link">
    <inertial>
      <origin rpy="0 0 0" xyz="0 0 0"/>
      <mass value="0.01"/>
      <inertia ixx="1e-6" ixy="0" ixz="0" iyy="1e-6" iyz="0" izz="1e-6"/>
    </inertial>
    <visual>
      <origin rpy="0 0 0" xyz="0 0 0"/>
      <geometry>
        <box size="0.02 0.02 0.02"/>
      </geometry>
      <material name="blue"/>
    </visual>
    <collision>
      <origin rpy="0 0 0" xyz="0 0 0"/>
      <geometry>
        <box size="0.02 0.02 0.02"/>
      </geometry>
    </collision>
  </link>
  <joint name="camera_joint" type="fixed">
    <parent link="base_link"/>
    <child link="camera_link"/>
    <origin xyz="0 -0.09 0.05" rpy="0 0 0"/> 
  </joint>
  <joint name="Revolute 1" type="continuous">
    <origin rpy="0 0 0" xyz="0.005 0.008443 -0.0115"/>
    <parent link="caster_fork_1"/>
    <child link="caster_wheel_1"/>
    <axis xyz="-1.0 0.0 0.0"/>
  </joint>
  <joint name="Revolute 2" type="continuous">
    <origin rpy="0 0 0" xyz="0.0 -0.08 -0.001"/>
    <parent link="base_link"/>
    <child link="caster_fork_1"/>
    <axis xyz="0.0 0.0 -1.0"/>
  </joint>
  <joint name="Revolute 3" type="continuous">
    <origin rpy="0 0 0" xyz="0.08 0.08 0.02"/>
    <parent link="base_link"/>
    <child link="left_wheel_1"/>
    <axis xyz="1.0 0.0 0.0"/>
  </joint>
  <joint name="Revolute 4" type="continuous">
    <origin rpy="0 0 0" xyz="-0.08 0.08 0.02"/>
    <parent link="base_link"/>
    <child link="right_wheel_1"/>
    <axis xyz="-1.0 0.0 0.0"/>
  </joint>
</robot>