<?xml version="1.0" ?>
<robot name="robot" xmlns:xacro="http://www.ros.org/wiki/xacro">

<xacro:include filename="$(find robot)/urdf/materials.xacro" />
<xacro:include filename="$(find robot)/urdf/robot.trans" />
<xacro:include filename="$(find robot)/urdf/robot.gazebo" />
<link name="base_link">
  <inertial>
    <origin xyz="-1.514808277263353e-17 5.101665553979481e-05 0.019999664794410715" rpy="0 0 0"/>
    <mass value="1.2728533351045312"/>
    <inertia ixx="0.004415" iyy="0.00256" izz="0.006635" ixy="0.0" iyz="-0.0" ixz="0.0"/>
  </inertial>
  <visual>
    <origin xyz="0 0 0" rpy="0 0 0"/>
    <geometry>
      <mesh filename="package://robot/meshes/base_link.stl" scale="0.001 0.001 0.001"/>
    </geometry>
    <material name="silver"/>
  </visual>
  <collision>
    <origin xyz="0 0 0" rpy="0 0 0"/>
    <geometry>
      <mesh filename="package://robot/meshes/base_link.stl" scale="0.001 0.001 0.001"/>
    </geometry>
  </collision>
</link>

<link name="caster_wheel_1">
  <inertial>
    <origin xyz="-0.005000000000000495 -2.058718588243691e-07 -2.149933009398808e-12" rpy="0 0 0"/>
    <mass value="0.0016434456569091604"/>
    <inertia ixx="0.0" iyy="0.0" izz="0.0" ixy="0.0" iyz="0.0" ixz="0.0"/>
  </inertial>
  <visual>
    <origin xyz="-0.005 0.071557 0.0125" rpy="0 0 0"/>
    <geometry>
      <mesh filename="package://robot/meshes/caster_wheel_1.stl" scale="0.001 0.001 0.001"/>
    </geometry>
    <material name="silver"/>
  </visual>
  <collision>
    <origin xyz="-0.005 0.071557 0.0125" rpy="0 0 0"/>
    <geometry>
      <mesh filename="package://robot/meshes/caster_wheel_1.stl" scale="0.001 0.001 0.001"/>
    </geometry>
  </collision>
</link>

<link name="caster_fork_1">
  <inertial>
    <origin xyz="-4.828898138961918e-16 0.003917233985619384 -0.006001009388864729" rpy="0 0 0"/>
    <mass value="0.001842425119376973"/>
    <inertia ixx="0.0" iyy="0.0" izz="0.0" ixy="-0.0" iyz="0.0" ixz="-0.0"/>
  </inertial>
  <visual>
    <origin xyz="-0.0 0.08 0.001" rpy="0 0 0"/>
    <geometry>
      <mesh filename="package://robot/meshes/caster_fork_1.stl" scale="0.001 0.001 0.001"/>
    </geometry>
    <material name="silver"/>
  </visual>
  <collision>
    <origin xyz="-0.0 0.08 0.001" rpy="0 0 0"/>
    <geometry>
      <mesh filename="package://robot/meshes/caster_fork_1.stl" scale="0.001 0.001 0.001"/>
    </geometry>
  </collision>
</link>

<link name="left_wheel_1">
  <inertial>
    <origin xyz="0.009999999999999995 0.0 0.0" rpy="0 0 0"/>
    <mass value="0.09349379737083224"/>
    <inertia ixx="7.5e-05" iyy="4.1e-05" izz="4.1e-05" ixy="0.0" iyz="0.0" ixz="0.0"/>
  </inertial>
  <visual>
    <origin xyz="-0.08 -0.08 -0.02" rpy="0 0 0"/>
    <geometry>
      <mesh filename="package://robot/meshes/left_wheel_1.stl" scale="0.001 0.001 0.001"/>
    </geometry>
    <material name="silver"/>
  </visual>
  <collision>
    <origin xyz="-0.08 -0.08 -0.02" rpy="0 0 0"/>
    <geometry>
      <mesh filename="package://robot/meshes/left_wheel_1.stl" scale="0.001 0.001 0.001"/>
    </geometry>
  </collision>
</link>

<link name="right_wheel_1">
  <inertial>
    <origin xyz="-0.009999999999999995 0.0 0.0" rpy="0 0 0"/>
    <mass value="0.09349379737083224"/>
    <inertia ixx="7.5e-05" iyy="4.1e-05" izz="4.1e-05" ixy="-0.0" iyz="0.0" ixz="0.0"/>
  </inertial>
  <visual>
    <origin xyz="0.08 -0.08 -0.02" rpy="0 0 0"/>
    <geometry>
      <mesh filename="package://robot/meshes/right_wheel_1.stl" scale="0.001 0.001 0.001"/>
    </geometry>
    <material name="silver"/>
  </visual>
  <collision>
    <origin xyz="0.08 -0.08 -0.02" rpy="0 0 0"/>
    <geometry>
      <mesh filename="package://robot/meshes/right_wheel_1.stl" scale="0.001 0.001 0.001"/>
    </geometry>
  </collision>
</link>

<joint name="Revolute 1" type="continuous">
  <origin xyz="0.005 0.008443 -0.0115" rpy="0 0 0"/>
  <parent link="caster_fork_1"/>
  <child link="caster_wheel_1"/>
  <axis xyz="-1.0 0.0 0.0"/>
</joint>

<joint name="Revolute 2" type="continuous">
  <origin xyz="0.0 -0.08 -0.001" rpy="0 0 0"/>
  <parent link="base_link"/>
  <child link="caster_fork_1"/>
  <axis xyz="0.0 0.0 -1.0"/>
</joint>

<joint name="Revolute 3" type="continuous">
  <origin xyz="0.08 0.08 0.02" rpy="0 0 0"/>
  <parent link="base_link"/>
  <child link="left_wheel_1"/>
  <axis xyz="1.0 0.0 0.0"/>
</joint>

<joint name="Revolute 4" type="continuous">
  <origin xyz="-0.08 0.08 0.02" rpy="0 0 0"/>
  <parent link="base_link"/>
  <child link="right_wheel_1"/>
  <axis xyz="-1.0 0.0 0.0"/>
</joint>

</robot>
