<?xml version="1.0" ?>
<robot name="robot">
  <material name="silver">
    <color rgba="0.700 0.700 0.700 1.000"/>
  </material>
  <transmission name="Revolute 1_tran">
    <type>transmission_interface/SimpleTransmission</type>
    <joint name="Revolute 1">
      <hardwareInterface>hardware_interface/EffortJointInterface</hardwareInterface>
    </joint>
    <actuator name="Revolute 1_actr">
      <hardwareInterface>hardware_interface/EffortJointInterface</hardwareInterface>
      <mechanicalReduction>1</mechanicalReduction>
    </actuator>
  </transmission>
  <transmission name="Revolute 2_tran">
    <type>transmission_interface/SimpleTransmission</type>
    <joint name="Revolute 2">
      <hardwareInterface>hardware_interface/EffortJointInterface</hardwareInterface>
    </joint>
    <actuator name="Revolute 2_actr">
      <hardwareInterface>hardware_interface/EffortJointInterface</hardwareInterface>
      <mechanicalReduction>1</mechanicalReduction>
    </actuator>
  </transmission>
  <transmission name="Revolute 3_tran">
    <type>transmission_interface/SimpleTransmission</type>
    <joint name="Revolute 3">
      <hardwareInterface>hardware_interface/EffortJointInterface</hardwareInterface>
    </joint>
    <actuator name="Revolute 3_actr">
      <hardwareInterface>hardware_interface/EffortJointInterface</hardwareInterface>
      <mechanicalReduction>1</mechanicalReduction>
    </actuator>
  </transmission>
  <gazebo>
    <plugin filename="libgazebo_ros_control.so" name="control"/>
  </gazebo>
  <gazebo reference="base_link">
    <material>Gazebo/Silver</material>
    <mu1>0.2</mu1>
    <mu2>0.2</mu2>
    <selfCollide>true</selfCollide>
    <gravity>true</gravity>
  </gazebo>
  <gazebo reference="right_wheel_1">
    <material>Gazebo/Silver</material>
    <mu1>0.2</mu1>
    <mu2>0.2</mu2>
    <selfCollide>true</selfCollide>
  </gazebo>
  <gazebo reference="left_wheel_1">
    <material>Gazebo/Silver</material>
    <mu1>0.2</mu1>
    <mu2>0.2</mu2>
    <selfCollide>true</selfCollide>
  </gazebo>
  <gazebo reference="lidar_1">
    <material>Gazebo/Silver</material>
    <mu1>0.2</mu1>
    <mu2>0.2</mu2>
    <selfCollide>true</selfCollide>
  </gazebo>
  <link name="base_link">
    <inertial>
      <origin rpy="0 0 0" xyz="1.355046717905403e-13 0.009343506444008564 0.019993521445171167"/>
      <mass value="1.2850428455001501"/>
      <inertia ixx="0.004491" ixy="0.0" ixz="0.0" iyy="0.002568" iyz="-2e-06" izz="0.006705"/>
    </inertial>
    <visual>
      <origin rpy="0 0 0" xyz="0 0 0"/>
      <geometry>
        <mesh filename="file:///Users/karel/Documents/robot/urdf/robot/meshes/base_link.stl" scale="0.001 0.001 0.001"/>
      </geometry>
      <material name="silver"/>
    </visual>
    <collision>
      <origin rpy="0 0 0" xyz="0 0 0"/>
      <geometry>
        <mesh filename="file:///Users/karel/Documents/robot/urdf/robot/meshes/base_link.stl" scale="0.001 0.001 0.001"/>
      </geometry>
    </collision>
  </link>
  <link name="right_wheel_1">
    <inertial>
      <origin rpy="0 0 0" xyz="0 0 0"/>
      <mass value="0.09349379737083224"/>
      <inertia ixx="7.5e-05" ixy="-0.0" ixz="0.0" iyy="4.1e-05" iyz="0.0" izz="4.1e-05"/>
    </inertial>
    <visual>
      <origin rpy="0 0 0" xyz="0 0 0"/>
      <geometry>
        <mesh filename="file:///Users/karel/Documents/robot/urdf/robot/meshes/right_wheel_1.stl" scale="0.0001 0.0001 0.0001"/>
      </geometry>
      <material name="silver"/>
    </visual>
    <collision>
      <origin rpy="0 0 0" xyz="0 0 0"/>
      <geometry>
        <mesh filename="file:///Users/karel/Documents/robot/urdf/robot/meshes/right_wheel_1.stl" scale="0.0001 0.0001 0.0001"/>
      </geometry>
    </collision>
  </link>
  <link name="left_wheel_1">
    <inertial>
      <origin rpy="0 0 0" xyz="0 0 0"/>
      <mass value="0.09349379737083224"/>
      <inertia ixx="7.5e-05" ixy="0.0" ixz="0.0" iyy="4.1e-05" iyz="0.0" izz="4.1e-05"/>
    </inertial>
    <visual>
      <origin rpy="0 0 0" xyz="0 0 0"/>
      <geometry>
        <mesh filename="file:///Users/karel/Documents/robot/urdf/robot/meshes/left_wheel_1.stl" scale="0.0001 0.0001 0.0001"/>
      </geometry>
      <material name="silver"/>
    </visual>
    <collision>
      <origin rpy="0 0 0" xyz="0 0 0"/>
      <geometry>
        <mesh filename="file:///Users/karel/Documents/robot/urdf/robot/meshes/left_wheel_1.stl" scale="0.0001 0.0001 0.0001"/>
      </geometry>
    </collision>
  </link>
  <link name="lidar_1">
    <inertial>
      <origin rpy="0 0 0" xyz="0 0 0"/>
      <mass value="0.039961058553662165"/>
      <inertia ixx="7e-06" ixy="0.0" ixz="-0.0" iyy="7e-06" iyz="0.0" izz="8e-06"/>
    </inertial>
    <visual>
      <origin rpy="0 0 0" xyz="0 0 0"/>
      <geometry>
        <mesh filename="file:///Users/karel/Documents/robot/urdf/robot/meshes/lidar_1.stl" scale="0.0001 0.0001 0.0001"/>
      </geometry>
      <material name="silver"/>
    </visual>
    <collision>
      <origin rpy="0 0 0" xyz="0 0 0"/>
      <geometry>
        <mesh filename="file:///Users/karel/Documents/robot/urdf/robot/meshes/lidar_1.stl" scale="0.0001 0.0001 0.0001"/>
      </geometry>
    </collision>
  </link>
  <joint name="Revolute 1" type="continuous">
    <origin rpy="0 0 0" xyz="-0.08 0.09 0.02"/>
    <parent link="base_link"/>
    <child link="right_wheel_1"/>
    <axis xyz="-1.0 0.0 0.0"/>
  </joint>
  <joint name="Revolute 2" type="continuous">
    <origin rpy="0 0 0" xyz="0.08 0.09 0.02"/>
    <parent link="base_link"/>
    <child link="left_wheel_1"/>
    <axis xyz="1.0 0.0 0.0"/>
  </joint>
  <joint name="Revolute 3" type="continuous">
    <origin rpy="0 0 0" xyz="0.0 -0.06 0.045"/>
    <parent link="base_link"/>
    <child link="lidar_1"/>
    <axis xyz="0.0 0.0 1.0"/>
  </joint>
</robot>