<?xml version="1.0" ?>
<robot name="balance">
  <material name="silver">
    <color rgba="0.700 0.700 0.700 1.000"/>
  </material>
  <transmission name="Revolute 1_tran">
    <type>transmission_interface/SimpleTransmission</type>
    <joint name="Revolute 1">
      <hardwareInterface>hardware_interface/EffortJointInterface</hardwareInterface>
    </joint>
    <actuator name="Revolute 1_actr">
      <hardwareInterface>hardware_interface/EffortJointInterface</hardwareInterface>
      <mechanicalReduction>1</mechanicalReduction>
    </actuator>
  </transmission>
  <transmission name="Revolute 2_tran">
    <type>transmission_interface/SimpleTransmission</type>
    <joint name="Revolute 2">
      <hardwareInterface>hardware_interface/EffortJointInterface</hardwareInterface>
    </joint>
    <actuator name="Revolute 2_actr">
      <hardwareInterface>hardware_interface/EffortJointInterface</hardwareInterface>
      <mechanicalReduction>1</mechanicalReduction>
    </actuator>
  </transmission>
  <gazebo>
    <plugin filename="libgazebo_ros_control.so" name="control"/>
  </gazebo>
  <gazebo reference="base_link">
    <material>Gazebo/Silver</material>
    <mu1>0.2</mu1>
    <mu2>0.2</mu2>
    <selfCollide>true</selfCollide>
    <gravity>true</gravity>
  </gazebo>
  <gazebo reference="right_wheel_1">
    <material>Gazebo/Silver</material>
    <mu1>0.2</mu1>
    <mu2>0.2</mu2>
    <selfCollide>true</selfCollide>
  </gazebo>
  <gazebo reference="left_wheel_1">
    <material>Gazebo/Silver</material>
    <mu1>0.2</mu1>
    <mu2>0.2</mu2>
    <selfCollide>true</selfCollide>
  </gazebo>
  <gazebo reference="balance_wheel_1">
    <material>Gazebo/Silver</material>
    <mu1>0.2</mu1>
    <mu2>0.2</mu2>
    <selfCollide>true</selfCollide>
  </gazebo>
  <link name="base_link">
    <inertial>
      <origin rpy="0 0 0" xyz="-3.298439565456548e-17 0.0 0.15518382600667469"/>
      <mass value="3"/>
      <inertia ixx="0.099393" ixy="-0.0" ixz="0.0" iyy="0.113338" iyz="0.0" izz="0.017848"/>
    </inertial>
    <visual>
      <origin rpy="0 0 0" xyz="0 0 0"/>
      <geometry>
        <mesh filename="meshes/base_link.stl" scale="0.001 0.001 0.001"/>
      </geometry>
      <material name="silver"/>
    </visual>
    <collision>
      <origin rpy="0 0 0" xyz="0 0 0"/>
      <geometry>
        <mesh filename="meshes/base_link.stl" scale="0.001 0.001 0.001"/>
      </geometry>
    </collision>
  </link>
  <link name="right_wheel_1">
    <inertial>
      <origin rpy="0 0 0" xyz="-0.025000000000000022 -3.695863830910979e-17 1.0408340855860843e-17"/>
      <mass value="2.5"/>
      <inertia ixx="0.002874" ixy="-0.0" ixz="-0.0" iyy="0.001621" iyz="0.0" izz="0.001621"/>
    </inertial>
    <visual>
      <origin rpy="0 0 0" xyz="0.195 -0.0 -0.019"/>
      <geometry>
        <mesh filename="meshes/right_wheel_1.stl" scale="0.001 0.001 0.001"/>
      </geometry>
      <material name="silver"/>
    </visual>
    <collision>
      <origin rpy="0 0 0" xyz="0.195 -0.0 -0.019"/>
      <geometry>
        <mesh filename="meshes/right_wheel_1.stl" scale="0.001 0.001 0.001"/>
      </geometry>
    </collision>
  </link>
  <link name="left_wheel_1">
    <inertial>
      <origin rpy="0 0 0" xyz="0.025000000000000022 -2.7718978731832345e-17 1.0408340855860843e-17"/>
      <mass value="2.5"/>
      <inertia ixx="0.002874" ixy="-0.0" ixz="-0.0" iyy="0.001621" iyz="0.0" izz="0.001621"/>
    </inertial>
    <visual>
      <origin rpy="0 0 0" xyz="-0.195 -0.0 -0.019"/>
      <geometry>
        <mesh filename="meshes/left_wheel_1.stl" scale="0.001 0.001 0.001"/>
      </geometry>
      <material name="silver"/>
    </visual>
    <collision>
      <origin rpy="0 0 0" xyz="-0.195 -0.0 -0.019"/>
      <geometry>
        <mesh filename="meshes/left_wheel_1.stl" scale="0.001 0.001 0.001"/>
      </geometry>
    </collision>
  </link>
  <link name="balance_wheel_1">
    <inertial>
      <origin rpy="0 0 0" xyz="8.315693619549702e-17 -2.7718978731832345e-17 0.025000000000000133"/>
      <mass value="2.5"/>
      <inertia ixx="0.001621" ixy="0.0" ixz="-0.0" iyy="0.001621" iyz="-0.0" izz="0.002874"/>
    </inertial>
    <visual>
      <origin rpy="0 0 0" xyz="-0.0 -0.0 -1.088"/>
      <geometry>
        <mesh filename="meshes/balance_wheel_1.stl" scale="0.001 0.001 0.001"/>
      </geometry>
      <material name="silver"/>
    </visual>
    <collision>
      <origin rpy="0 0 0" xyz="-0.0 -0.0 -1.088"/>
      <geometry>
        <mesh filename="meshes/balance_wheel_1.stl" scale="0.001 0.001 0.001"/>
      </geometry>
    </collision>
  </link>
  <joint name="Revolute 1" type="continuous">
    <origin rpy="0 0 0" xyz="-0.195 0.0 0.019"/>
    <parent link="base_link"/>
    <child link="right_wheel_1"/>
    <axis xyz="-1.0 0.0 0.0"/>
  </joint>
  <joint name="Revolute 2" type="continuous">
    <origin rpy="0 0 0" xyz="0.195 0.0 0.019"/>
    <parent link="base_link"/>
    <child link="left_wheel_1"/>
    <axis xyz="1.0 0.0 0.0"/>
  </joint>
  <joint name="Rigid 3" type="fixed">
    <origin rpy="0 0 0" xyz="0.0 0.0 1.088"/>
    <parent link="base_link"/>
    <child link="balance_wheel_1"/>
  </joint>
</robot>
